[{"name": "unittest.loader._FailedTest.test.test_usemodule", "status": "errored", "message": "Failed to import test module: test.test_usemodule\nTraceback (most recent call last):\n  File \"/usr/lib/python3.6/unittest/loader.py\", line 428, in _find_test_path\n    module = self._get_module_from_name(name)\n  File \"/usr/lib/python3.6/unittest/loader.py\", line 369, in _get_module_from_name\n    __import__(name)\n  File \"/home/du_ds/Documents/Git/PythonDataAnalysisCourse/hy-data-analysis-with-python-summer-2019/part01-e20_usemodule/test/test_usemodule.py\", line 13, in <module>\n    from src import usemodule\n  File \"/home/du_ds/Documents/Git/PythonDataAnalysisCourse/hy-data-analysis-with-python-summer-2019/part01-e20_usemodule/src/usemodule.py\", line 12\n    if __name__ == \"__main__\":\n     ^\nIndentationError: expected an indented block\n", "passed": false, "points": [], "backtrace": ["  File \"/usr/lib/python3.6/unittest/case.py\", line 59, in testPartExecutor\n    yield\n", "  File \"/usr/lib/python3.6/unittest/case.py\", line 605, in run\n    testMethod()\n", "  File \"/usr/lib/python3.6/unittest/loader.py\", line 34, in testFailure\n    raise self._exception\n"]}]