[{"name": "test.test_distinct_characters.DistinctCharacters.test_empty", "status": "passed", "message": "", "passed": true, "points": ["p01-12.1"], "backtrace": []}, {"name": "test.test_distinct_characters.DistinctCharacters.test_first", "status": "errored", "message": "'check'", "passed": false, "points": ["p01-12.1"], "backtrace": ["  File \"/usr/lib/python3.6/unittest/case.py\", line 59, in testPartExecutor\n    yield\n", "  File \"/usr/lib/python3.6/unittest/case.py\", line 605, in run\n    testMethod()\n", "  File \"/home/du_ds/Documents/Git/PythonDataAnalysisCourse/hy-data-analysis-with-python-summer-2019/part01-e12_distinct_characters/test/test_distinct_characters.py\", line 37, in test_first\n    self.assertEqual(d[\"check\"], 4, msg=\"Number of distinct characters of word 'check' was incorrect!\")\n"]}, {"name": "test.test_distinct_characters.DistinctCharacters.test_random", "status": "failed", "message": "0 != 18", "passed": false, "points": ["p01-12.1"], "backtrace": ["  File \"/usr/lib/python3.6/unittest/case.py\", line 59, in testPartExecutor\n    yield\n", "  File \"/usr/lib/python3.6/unittest/case.py\", line 605, in run\n    testMethod()\n", "  File \"/home/du_ds/Documents/Git/PythonDataAnalysisCourse/hy-data-analysis-with-python-summer-2019/part01-e12_distinct_characters/test/test_distinct_characters.py\", line 50, in test_random\n    self.assertEqual(len(d), len(set(L)))\n", "  File \"/usr/lib/python3.6/unittest/case.py\", line 829, in assertEqual\n    assertion_func(first, second, msg=msg)\n", "  File \"/usr/lib/python3.6/unittest/case.py\", line 822, in _baseAssertEqual\n    raise self.failureException(msg)\n"]}]