[{"name": "test.test_row_and_column_vectors.RowsAndColumns.test_column_content", "status": "passed", "message": "", "passed": true, "points": ["p02-12.1"], "backtrace": []}, {"name": "test.test_row_and_column_vectors.RowsAndColumns.test_column_count", "status": "failed", "message": "0 != 5 : Wrong number of columns", "passed": false, "points": ["p02-12.1"], "backtrace": ["  File \"/usr/lib/python3.6/unittest/case.py\", line 59, in testPartExecutor\n    yield\n", "  File \"/usr/lib/python3.6/unittest/case.py\", line 605, in run\n    testMethod()\n", "  File \"/home/du_ds/Documents/Git/PythonDataAnalysisCourse/hy-data-analysis-with-python-summer-2019/part02-e12_row_and_column_vectors/test/test_row_and_column_vectors.py\", line 41, in test_column_count\n    self.assertEqual(len(get_column_vectors(a)), 5, msg=\"Wrong number of columns\")\n", "  File \"/usr/lib/python3.6/unittest/case.py\", line 829, in assertEqual\n    assertion_func(first, second, msg=msg)\n", "  File \"/usr/lib/python3.6/unittest/case.py\", line 822, in _baseAssertEqual\n    raise self.failureException(msg)\n"]}, {"name": "test.test_row_and_column_vectors.RowsAndColumns.test_columns_types", "status": "passed", "message": "", "passed": true, "points": ["p02-12.1"], "backtrace": []}, {"name": "test.test_row_and_column_vectors.RowsAndColumns.test_row_content", "status": "passed", "message": "", "passed": true, "points": ["p02-12.1"], "backtrace": []}, {"name": "test.test_row_and_column_vectors.RowsAndColumns.test_row_count", "status": "failed", "message": "0 != 3 : Wrong number of rows", "passed": false, "points": ["p02-12.1"], "backtrace": ["  File \"/usr/lib/python3.6/unittest/case.py\", line 59, in testPartExecutor\n    yield\n", "  File \"/usr/lib/python3.6/unittest/case.py\", line 605, in run\n    testMethod()\n", "  File \"/home/du_ds/Documents/Git/PythonDataAnalysisCourse/hy-data-analysis-with-python-summer-2019/part02-e12_row_and_column_vectors/test/test_row_and_column_vectors.py\", line 37, in test_row_count\n    self.assertEqual(len(get_row_vectors(a)), 3, msg=\"Wrong number of rows\")\n", "  File \"/usr/lib/python3.6/unittest/case.py\", line 829, in assertEqual\n    assertion_func(first, second, msg=msg)\n", "  File \"/usr/lib/python3.6/unittest/case.py\", line 822, in _baseAssertEqual\n    raise self.failureException(msg)\n"]}, {"name": "test.test_row_and_column_vectors.RowsAndColumns.test_row_types", "status": "passed", "message": "", "passed": true, "points": ["p02-12.1"], "backtrace": []}]