[{"name": "test.test_summary.Summary.test_calls", "status": "failed", "message": "Expected 'open' to have been called.", "passed": false, "points": ["p02-05.1"], "backtrace": ["  File \"/usr/lib/python3.6/unittest/case.py\", line 59, in testPartExecutor\n    yield\n", "  File \"/usr/lib/python3.6/unittest/case.py\", line 605, in run\n    testMethod()\n", "  File \"/home/du_ds/Documents/Git/PythonDataAnalysisCourse/hy-data-analysis-with-python-summer-2019/part02-e05_summary/test/test_summary.py\", line 50, in test_calls\n    o.assert_called()\n", "  File \"/usr/lib/python3.6/unittest/mock.py\", line 786, in assert_called\n    raise AssertionError(msg)\n"]}, {"name": "test.test_summary.Summary.test_main", "status": "failed", "message": "0 != 7 : Expected 7 calls to summary for 7 command line parameters!", "passed": false, "points": ["p02-05.1"], "backtrace": ["  File \"/usr/lib/python3.6/unittest/case.py\", line 59, in testPartExecutor\n    yield\n", "  File \"/usr/lib/python3.6/unittest/case.py\", line 605, in run\n    testMethod()\n", "  File \"/home/du_ds/Documents/Git/PythonDataAnalysisCourse/hy-data-analysis-with-python-summer-2019/part02-e05_summary/test/test_summary.py\", line 61, in test_main\n    msg=\"Expected %i calls to summary for %i command line parameters!\" % (n,n))\n", "  File \"/usr/lib/python3.6/unittest/case.py\", line 829, in assertEqual\n    assertion_func(first, second, msg=msg)\n", "  File \"/usr/lib/python3.6/unittest/case.py\", line 822, in _baseAssertEqual\n    raise self.failureException(msg)\n"]}, {"name": "test.test_summary.Summary.test_missing_file", "status": "failed", "message": "FileNotFoundError not raised", "passed": false, "points": ["p02-05.1"], "backtrace": ["  File \"/usr/lib/python3.6/unittest/case.py\", line 59, in testPartExecutor\n    yield\n", "  File \"/usr/lib/python3.6/unittest/case.py\", line 605, in run\n    testMethod()\n", "  File \"/home/du_ds/Documents/Git/PythonDataAnalysisCourse/hy-data-analysis-with-python-summer-2019/part02-e05_summary/test/test_summary.py\", line 44, in test_missing_file\n    summary(\"doesnotexist\")\n", "  File \"/usr/lib/python3.6/unittest/case.py\", line 203, in __exit__\n    self._raiseFailure(\"{} not raised\".format(exc_name))\n", "  File \"/usr/lib/python3.6/unittest/case.py\", line 135, in _raiseFailure\n    raise self.test_case.failureException(msg)\n"]}, {"name": "test.test_summary.Summary.test_one", "status": "failed", "message": "0 != 51.4 within 4 places : Wrong sum for file example.txt!", "passed": false, "points": ["p02-05.1"], "backtrace": ["  File \"/usr/lib/python3.6/unittest/case.py\", line 59, in testPartExecutor\n    yield\n", "  File \"/usr/lib/python3.6/unittest/case.py\", line 605, in run\n    testMethod()\n", "  File \"/home/du_ds/Documents/Git/PythonDataAnalysisCourse/hy-data-analysis-with-python-summer-2019/part02-e05_summary/test/test_summary.py\", line 23, in test_one\n    self.assertAlmostEqual(s, 51.400000, places=4, msg=\"Wrong sum for file example.txt!\")\n", "  File \"/usr/lib/python3.6/unittest/case.py\", line 878, in assertAlmostEqual\n    raise self.failureException(msg)\n"]}, {"name": "test.test_summary.Summary.test_three", "status": "failed", "message": "0 != 50.0 within 4 places : Wrong std for file example3.txt!", "passed": false, "points": ["p02-05.2"], "backtrace": ["  File \"/usr/lib/python3.6/unittest/case.py\", line 59, in testPartExecutor\n    yield\n", "  File \"/usr/lib/python3.6/unittest/case.py\", line 605, in run\n    testMethod()\n", "  File \"/home/du_ds/Documents/Git/PythonDataAnalysisCourse/hy-data-analysis-with-python-summer-2019/part02-e05_summary/test/test_summary.py\", line 39, in test_three\n    self.assertAlmostEqual(d, 50.000000, places=4, msg=\"Wrong std for file example3.txt!\")\n", "  File \"/usr/lib/python3.6/unittest/case.py\", line 878, in assertAlmostEqual\n    raise self.failureException(msg)\n"]}, {"name": "test.test_summary.Summary.test_two", "status": "failed", "message": "0 != 5446.2 within 4 places : Wrong sum for file example2.txt!", "passed": false, "points": ["p02-05.1"], "backtrace": ["  File \"/usr/lib/python3.6/unittest/case.py\", line 59, in testPartExecutor\n    yield\n", "  File \"/usr/lib/python3.6/unittest/case.py\", line 605, in run\n    testMethod()\n", "  File \"/home/du_ds/Documents/Git/PythonDataAnalysisCourse/hy-data-analysis-with-python-summer-2019/part02-e05_summary/test/test_summary.py\", line 30, in test_two\n    self.assertAlmostEqual(s, 5446.200000, places=4, msg=\"Wrong sum for file example2.txt!\")\n", "  File \"/usr/lib/python3.6/unittest/case.py\", line 878, in assertAlmostEqual\n    raise self.failureException(msg)\n"]}]