[{"name": "test.test_find_matching.FindMatching.test_calls", "status": "failed", "message": "Expected 'enumerate' to have been called.", "passed": false, "points": ["p01-14.1"], "backtrace": ["  File \"/usr/lib/python3.6/unittest/case.py\", line 59, in testPartExecutor\n    yield\n", "  File \"/usr/lib/python3.6/unittest/case.py\", line 605, in run\n    testMethod()\n", "  File \"/home/du_ds/Documents/Git/PythonDataAnalysisCourse/hy-data-analysis-with-python-summer-2019/part01-e14_find_matching/test/test_find_matching.py\", line 24, in test_calls\n    p.assert_called()\n", "  File \"/usr/lib/python3.6/unittest/mock.py\", line 786, in assert_called\n    raise AssertionError(msg)\n"]}, {"name": "test.test_find_matching.FindMatching.test_empty", "status": "passed", "message": "", "passed": true, "points": ["p01-14.1"], "backtrace": []}, {"name": "test.test_find_matching.FindMatching.test_first", "status": "failed", "message": "Lists differ: [] != [0, 1, 3]\n\nSecond list contains 3 additional elements.\nFirst extra element 0:\n0\n\n- []\n+ [0, 1, 3]", "passed": false, "points": ["p01-14.1"], "backtrace": ["  File \"/usr/lib/python3.6/unittest/case.py\", line 59, in testPartExecutor\n    yield\n", "  File \"/usr/lib/python3.6/unittest/case.py\", line 605, in run\n    testMethod()\n", "  File \"/home/du_ds/Documents/Git/PythonDataAnalysisCourse/hy-data-analysis-with-python-summer-2019/part01-e14_find_matching/test/test_find_matching.py\", line 19, in test_first\n    self.assertEqual(result, [0,1,3])\n", "  File \"/usr/lib/python3.6/unittest/case.py\", line 829, in assertEqual\n    assertion_func(first, second, msg=msg)\n", "  File \"/usr/lib/python3.6/unittest/case.py\", line 1028, in assertListEqual\n    self.assertSequenceEqual(list1, list2, msg, seq_type=list)\n", "  File \"/usr/lib/python3.6/unittest/case.py\", line 1010, in assertSequenceEqual\n    self.fail(msg)\n", "  File \"/usr/lib/python3.6/unittest/case.py\", line 670, in fail\n    raise self.failureException(msg)\n"]}]