[{"name": "test.test_file_count.FileCount.test_calls", "status": "failed", "message": "Expected 'open' to have been called once. Called 0 times.", "passed": false, "points": ["p02-06.1"], "backtrace": ["  File \"/usr/lib/python3.6/unittest/case.py\", line 59, in testPartExecutor\n    yield\n", "  File \"/usr/lib/python3.6/unittest/case.py\", line 605, in run\n    testMethod()\n", "  File \"/home/du_ds/Documents/Git/PythonDataAnalysisCourse/hy-data-analysis-with-python-summer-2019/part02-e06_file_count/test/test_file_count.py\", line 29, in test_calls\n    o.assert_called_once()\n", "  File \"/usr/lib/python3.6/unittest/mock.py\", line 795, in assert_called_once\n    raise AssertionError(msg)\n"]}, {"name": "test.test_file_count.FileCount.test_first", "status": "failed", "message": "0 != 8 : Wrong number of lines for file 'test.txt'!", "passed": false, "points": ["p02-06.1"], "backtrace": ["  File \"/usr/lib/python3.6/unittest/case.py\", line 59, in testPartExecutor\n    yield\n", "  File \"/usr/lib/python3.6/unittest/case.py\", line 605, in run\n    testMethod()\n", "  File \"/home/du_ds/Documents/Git/PythonDataAnalysisCourse/hy-data-analysis-with-python-summer-2019/part02-e06_file_count/test/test_file_count.py\", line 21, in test_first\n    self.assertEqual(l, 8, msg=\"Wrong number of lines for file 'test.txt'!\")\n", "  File \"/usr/lib/python3.6/unittest/case.py\", line 829, in assertEqual\n    assertion_func(first, second, msg=msg)\n", "  File \"/usr/lib/python3.6/unittest/case.py\", line 822, in _baseAssertEqual\n    raise self.failureException(msg)\n"]}, {"name": "test.test_file_count.FileCount.test_main", "status": "failed", "message": "0 != 7 : Wrong number of calls to function 'file_count' for 7 command line parameters!", "passed": false, "points": ["p02-06.2"], "backtrace": ["  File \"/usr/lib/python3.6/unittest/case.py\", line 59, in testPartExecutor\n    yield\n", "  File \"/usr/lib/python3.6/unittest/case.py\", line 605, in run\n    testMethod()\n", "  File \"/home/du_ds/Documents/Git/PythonDataAnalysisCourse/hy-data-analysis-with-python-summer-2019/part02-e06_file_count/test/test_file_count.py\", line 40, in test_main\n    msg=\"Wrong number of calls to function 'file_count' for %i command line parameters!\" % n)\n", "  File \"/usr/lib/python3.6/unittest/case.py\", line 829, in assertEqual\n    assertion_func(first, second, msg=msg)\n", "  File \"/usr/lib/python3.6/unittest/case.py\", line 822, in _baseAssertEqual\n    raise self.failureException(msg)\n"]}]